248.*
248.*
cju8bzzy2s66m08016z6mouqt.*
cju8bzzy2s66m08016z6mouqt.*
321.*
385.*
321.*
385.*
cju8bzzy2s66m08016z6mouqt  ----load----
img: (622, 529)
mask: (622, 529)
248  ----load----
img: (384, 288)
mask: (384, 288)
321  ----load----
385  ----load----
img: (384, 288)
img: (384, 288)
mask: (384, 288)
mask: (384, 288)
438.*
438.*
438  ----load----
img: (384, 288)
mask: (384, 288)
86.*
86.*
cju88msmoo3470817m441j4sg.*
cju88msmoo3470817m441j4sg.*
86  ----load----
img: (384, 288)
mask: (384, 288)
cju88msmoo3470817m441j4sg  ----load----
img: (615, 530)
mask: (615, 530)
cju2qqn5ys4uo0988ewrt2ip2.*
cju2qqn5ys4uo0988ewrt2ip2.*
cju2qqn5ys4uo0988ewrt2ip2  ----load----
img: (626, 546)
mask: (626, 546)
295.*
295.*
295  ----load----
img: (384, 288)
mask: (384, 288)
INFO: Starting training:
        Epochs:          5
        Batch size:      5
        Learning rate:   1e-05
        Training size:   1305
        Validation size: 145
        Checkpoints:     True
        Device:          cuda
        Images scaling:  0.5
        Mixed Precision: True
Epoch 1/5:   0%|                                                                     | 0/1305 [00:00<?, ?img/s]
Traceback (most recent call last):
  File "train.py", line 188, in <module>
    amp=args.amp)
  File "train.py", line 76, in train_net
    for batch in train_loader:
  File "/home/nicolas/anaconda3/envs/josue_torch/lib/python3.7/site-packages/torch/utils/data/dataloader.py", line 521, in __next__
    data = self._next_data()
  File "/home/nicolas/anaconda3/envs/josue_torch/lib/python3.7/site-packages/torch/utils/data/dataloader.py", line 1203, in _next_data
    return self._process_data(data)
  File "/home/nicolas/anaconda3/envs/josue_torch/lib/python3.7/site-packages/torch/utils/data/dataloader.py", line 1229, in _process_data
    data.reraise()
  File "/home/nicolas/anaconda3/envs/josue_torch/lib/python3.7/site-packages/torch/_utils.py", line 434, in reraise
    raise exception
AttributeError: Caught AttributeError in DataLoader worker process 0.
Original Traceback (most recent call last):
  File "/home/nicolas/anaconda3/envs/josue_torch/lib/python3.7/site-packages/torch/utils/data/_utils/worker.py", line 287, in _worker_loop
    data = fetcher.fetch(index)
  File "/home/nicolas/anaconda3/envs/josue_torch/lib/python3.7/site-packages/torch/utils/data/_utils/fetch.py", line 49, in fetch
    data = [self.dataset[idx] for idx in possibly_batched_index]
  File "/home/nicolas/anaconda3/envs/josue_torch/lib/python3.7/site-packages/torch/utils/data/_utils/fetch.py", line 49, in <listcomp>
    data = [self.dataset[idx] for idx in possibly_batched_index]
  File "/home/nicolas/anaconda3/envs/josue_torch/lib/python3.7/site-packages/torch/utils/data/dataset.py", line 363, in __getitem__
    return self.dataset[self.indices[idx]]
  File "/home/nicolas/workspace_josue/Pytorch-UNet/utils/data_loading.py", line 77, in __getitem__
    img = self.preprocess(img, self.scale, is_mask=False)
  File "/home/nicolas/workspace_josue/Pytorch-UNet/utils/data_loading.py", line 34, in preprocess
    print(pil_img.shape, pil_img.mode,'mask',is_mask)
  File "/home/nicolas/anaconda3/envs/josue_torch/lib/python3.7/site-packages/PIL/Image.py", line 546, in __getattr__
    raise AttributeError(name)
AttributeError: shape