INFO: Starting training:
        Epochs:          5
        Batch size:      1
        Learning rate:   1e-05
        Training size:   1305
        Validation size: 145
        Checkpoints:     True
        Device:          cuda
        Images size:     [250.0, 250.0]
        Mixed Precision: True
Epoch 1/5:   0%|                                                                     | 0/1305 [00:00<?, ?img/s]
Traceback (most recent call last):
  File "train.py", line 194, in <module>
    amp=args.amp)
  File "train.py", line 77, in train_net
    for batch in train_loader:
  File "/home/nicolas/anaconda3/envs/josue_torch/lib/python3.7/site-packages/torch/utils/data/dataloader.py", line 521, in __next__
    data = self._next_data()
  File "/home/nicolas/anaconda3/envs/josue_torch/lib/python3.7/site-packages/torch/utils/data/dataloader.py", line 1203, in _next_data
    return self._process_data(data)
  File "/home/nicolas/anaconda3/envs/josue_torch/lib/python3.7/site-packages/torch/utils/data/dataloader.py", line 1229, in _process_data
    data.reraise()
  File "/home/nicolas/anaconda3/envs/josue_torch/lib/python3.7/site-packages/torch/_utils.py", line 434, in reraise
    raise exception
ValueError: Caught ValueError in DataLoader worker process 0.
Original Traceback (most recent call last):
  File "/home/nicolas/anaconda3/envs/josue_torch/lib/python3.7/site-packages/torch/utils/data/_utils/worker.py", line 287, in _worker_loop
    data = fetcher.fetch(index)
  File "/home/nicolas/anaconda3/envs/josue_torch/lib/python3.7/site-packages/torch/utils/data/_utils/fetch.py", line 49, in fetch
    data = [self.dataset[idx] for idx in possibly_batched_index]
  File "/home/nicolas/anaconda3/envs/josue_torch/lib/python3.7/site-packages/torch/utils/data/_utils/fetch.py", line 49, in <listcomp>
    data = [self.dataset[idx] for idx in possibly_batched_index]
  File "/home/nicolas/anaconda3/envs/josue_torch/lib/python3.7/site-packages/torch/utils/data/dataset.py", line 363, in __getitem__
    return self.dataset[self.indices[idx]]
  File "/home/nicolas/workspace_josue/Pytorch-UNet/utils/data_loading.py", line 78, in __getitem__
    mask = self.preprocess(mask, self.img_size, is_mask=True)
  File "/home/nicolas/workspace_josue/Pytorch-UNet/utils/data_loading.py", line 40, in preprocess
    img_ndarray = img_ndarray.transpose((2, 0, 1))
ValueError: axes don't match array