2021-11-18 21:55:16,025 INFO    MainThread:9330 [internal.py:wandb_internal():90] W&B internal server running at pid: 9330, started at: 2021-11-18 21:55:16.025456
2021-11-18 21:55:16,026 DEBUG   HandlerThread:9330 [handler.py:handle_request():130] handle_request: check_version
2021-11-18 21:55:16,027 INFO    WriterThread:9330 [datastore.py:open_for_write():77] open: /home/nicolas/workspace_josue/Pytorch-UNet/wandb/run-20211118_215515-3502wyf8/run-3502wyf8.wandb
2021-11-18 21:55:16,027 DEBUG   SenderThread:9330 [sender.py:send():238] send: header
2021-11-18 21:55:16,027 DEBUG   SenderThread:9330 [sender.py:send_request():252] send_request: check_version
2021-11-18 21:55:16,506 DEBUG   SenderThread:9330 [sender.py:send():238] send: run
2021-11-18 21:55:16,507 INFO    SenderThread:9330 [sender.py:_maybe_setup_resume():506] checking resume status for None/U-Net/3502wyf8
2021-11-18 21:55:16,795 ERROR   SenderThread:9330 [internal_api.py:execute():144] 401 response executing GraphQL.
2021-11-18 21:55:16,796 ERROR   SenderThread:9330 [internal_api.py:execute():145] {"errors":[{"message":"permission denied","path":["upsertBucket"],"extensions":{"code":"PERMISSION_ERROR"}}],"data":{"upsertBucket":null}}
2021-11-18 21:55:17,507 INFO    HandlerThread:9330 [handler.py:finish():731] shutting down handler
2021-11-18 21:55:17,507 INFO    WriterThread:9330 [datastore.py:close():281] close: /home/nicolas/workspace_josue/Pytorch-UNet/wandb/run-20211118_215515-3502wyf8/run-3502wyf8.wandb
2021-11-18 21:55:17,508 ERROR   MainThread:9330 [internal.py:wandb_internal():158] Thread SenderThread:
Traceback (most recent call last):
  File "/home/nicolas/anaconda3/envs/josue_torch/lib/python3.7/site-packages/wandb/sdk/lib/retry.py", line 102, in __call__
    result = self._call_fn(*args, **kwargs)
  File "/home/nicolas/anaconda3/envs/josue_torch/lib/python3.7/site-packages/wandb/sdk/internal/internal_api.py", line 147, in execute
    six.reraise(*sys.exc_info())
  File "/home/nicolas/anaconda3/envs/josue_torch/lib/python3.7/site-packages/six.py", line 719, in reraise
    raise value
  File "/home/nicolas/anaconda3/envs/josue_torch/lib/python3.7/site-packages/wandb/sdk/internal/internal_api.py", line 141, in execute
    return self.client.execute(*args, **kwargs)
  File "/home/nicolas/anaconda3/envs/josue_torch/lib/python3.7/site-packages/wandb/vendor/gql-0.2.0/gql/client.py", line 52, in execute
    result = self._get_result(document, *args, **kwargs)
  File "/home/nicolas/anaconda3/envs/josue_torch/lib/python3.7/site-packages/wandb/vendor/gql-0.2.0/gql/client.py", line 60, in _get_result
    return self.transport.execute(document, *args, **kwargs)
  File "/home/nicolas/anaconda3/envs/josue_torch/lib/python3.7/site-packages/wandb/vendor/gql-0.2.0/gql/transport/requests.py", line 39, in execute
    request.raise_for_status()
  File "/home/nicolas/anaconda3/envs/josue_torch/lib/python3.7/site-packages/requests/models.py", line 953, in raise_for_status
    raise HTTPError(http_error_msg, response=self)
requests.exceptions.HTTPError: 401 Client Error: Unauthorized for url: https://api.wandb.ai/graphql

During handling of the above exception, another exception occurred:

Traceback (most recent call last):
  File "/home/nicolas/anaconda3/envs/josue_torch/lib/python3.7/site-packages/wandb/apis/normalize.py", line 24, in wrapper
    return func(*args, **kwargs)
  File "/home/nicolas/anaconda3/envs/josue_torch/lib/python3.7/site-packages/wandb/sdk/internal/internal_api.py", line 1270, in upsert_run
    response = self.gql(mutation, variable_values=variable_values, **kwargs)
  File "/home/nicolas/anaconda3/envs/josue_torch/lib/python3.7/site-packages/wandb/sdk/lib/retry.py", line 118, in __call__
    if not check_retry_fn(e):
  File "/home/nicolas/anaconda3/envs/josue_torch/lib/python3.7/site-packages/wandb/util.py", line 817, in no_retry_auth
    raise CommError("Invalid or missing api_key.  Run wandb login")
wandb.errors.CommError: Invalid or missing api_key.  Run wandb login

During handling of the above exception, another exception occurred:

Traceback (most recent call last):
  File "/home/nicolas/anaconda3/envs/josue_torch/lib/python3.7/site-packages/wandb/sdk/internal/internal_util.py", line 52, in run
    self._run()
  File "/home/nicolas/anaconda3/envs/josue_torch/lib/python3.7/site-packages/wandb/sdk/internal/internal_util.py", line 102, in _run
    self._process(record)
  File "/home/nicolas/anaconda3/envs/josue_torch/lib/python3.7/site-packages/wandb/sdk/internal/internal.py", line 291, in _process
    self._sm.send(record)
  File "/home/nicolas/anaconda3/envs/josue_torch/lib/python3.7/site-packages/wandb/sdk/internal/sender.py", line 240, in send
    send_handler(record)
  File "/home/nicolas/anaconda3/envs/josue_torch/lib/python3.7/site-packages/wandb/sdk/internal/sender.py", line 708, in send_run
    self._init_run(run, config_value_dict)
  File "/home/nicolas/anaconda3/envs/josue_torch/lib/python3.7/site-packages/wandb/sdk/internal/sender.py", line 746, in _init_run
    commit=run.git.last_commit or None,
  File "/home/nicolas/anaconda3/envs/josue_torch/lib/python3.7/site-packages/wandb/apis/normalize.py", line 62, in wrapper
    six.reraise(CommError, CommError(message, err), sys.exc_info()[2])
  File "/home/nicolas/anaconda3/envs/josue_torch/lib/python3.7/site-packages/six.py", line 718, in reraise
    raise value.with_traceback(tb)
  File "/home/nicolas/anaconda3/envs/josue_torch/lib/python3.7/site-packages/wandb/apis/normalize.py", line 24, in wrapper
    return func(*args, **kwargs)
  File "/home/nicolas/anaconda3/envs/josue_torch/lib/python3.7/site-packages/wandb/sdk/internal/internal_api.py", line 1270, in upsert_run
    response = self.gql(mutation, variable_values=variable_values, **kwargs)
  File "/home/nicolas/anaconda3/envs/josue_torch/lib/python3.7/site-packages/wandb/sdk/lib/retry.py", line 118, in __call__
    if not check_retry_fn(e):
  File "/home/nicolas/anaconda3/envs/josue_torch/lib/python3.7/site-packages/wandb/util.py", line 817, in no_retry_auth
    raise CommError("Invalid or missing api_key.  Run wandb login")
wandb.errors.CommError: Invalid or missing api_key.  Run wandb login
2021-11-18 21:55:19,523 INFO    MainThread:9330 [internal.py:handle_exit():77] Internal process exited
